"exception": "Traceback (most recent call last):\n  File \"/Users/luq89/PycharmProjects/FastAPIProject1/app/routers/base.py\", line 78, in classify\n    perform_classification()\n  File \"/Users/luq89/PycharmProjects/FastAPIProject1/app/service/classification/classify.py\", line 14, in perform_classification\n    raise ClassificationException('Classification failed', status_code=422)\ncommon.exceptions.pnc_exceptions.ClassificationException: Classification failed"
"exception": "Traceback (most recent call last):\n  File \"/Users/luq89/PycharmProjects/FastAPIProject1/.venv/lib/python3.10/site-packages/starlette/_exception_handler.py\", line 42, in wrapped_app\n    await app(scope, receive, sender)\n  File \"/Users/luq89/PycharmProjects/FastAPIProject1/.venv/lib/python3.10/site-packages/starlette/routing.py\", line 73, in app\n    response = await f(request)\n  File \"/Users/luq89/PycharmProjects/FastAPIProject1/.venv/lib/python3.10/site-packages/fastapi/routing.py\", line 301, in app\n    raw_response = await run_endpoint_function(\n  File \"/Users/luq89/PycharmProjects/FastAPIProject1/.venv/lib/python3.10/site-packages/fastapi/routing.py\", line 212, in run_endpoint_function\n    return await dependant.call(**values)\nFile \"/Users/luq89/PycharmProjects/FastAPIProject1/app/routers/base.py\", line 78, in classify\n    perform_classification()\n  File \"/Users/luq89/PycharmProjects/FastAPIProject1/app/service/classification/classify.py\", line 14, in perform_classification\n    raise ClassificationException('Classification failed', status_code=422)\ncommon.exceptions.pnc_exceptions.ClassificationException: Classification failed"